ValueError
Python 3.9.7: E:\Anaconda3\envs\imgproapp\python.exe
Sat Dec 25 20:22:20 2021

A problem occurred in a Python script.  Here is the sequence of
function calls leading up to the error, in the order they occurred.

 E:\BaiduNetdiskWorkspace\Cloud_PythonProgramming\img-proc-app\widgets\ImgFrame.py in dropEvent(self=<widgets.ImgFrame.ImgFrame object>, event=<PyQt5.QtGui.QDropEvent object>)
  128             self.dir_img = event.mimeData().urls()[0].toLocalFile()
  129             self.imQT = QtGui.QImage(self.dir_img)
  130         self.CV.Q2CVimg(self.imQT)
  131         self.repaint()
  132 
self = <widgets.ImgFrame.ImgFrame object>
self.CV = <plugins.ipc.AppImg object>
self.CV.Q2CVimg = <bound method AppImg.Q2CVimg of <plugins.ipc.AppImg object>>
self.imQT = <PyQt5.QtGui.QImage object>

 E:\BaiduNetdiskWorkspace\Cloud_PythonProgramming\img-proc-app\plugins\ipc.py in Q2CVimg(self=<plugins.ipc.AppImg object>, Qimg=<PyQt5.QtGui.QImage object>)
  108                 ptr = Qimg.bits()
  109                 ptr.setsize(Qimg.byteCount())
  110                 CVimg = array(ptr, dtype=uint8).reshape(temp_shape)
  111                 CVimg = CVimg[..., ::-1]
  112 
CVimg undefined
global array = <built-in function array>
ptr = <sip.voidptr object>
dtype undefined
global uint8 = <class 'numpy.uint8'>
).reshape = <method 'reshape' of 'numpy.generic' objects>
temp_shape = (3648, 2736, 3)
ValueError: cannot reshape array of size 9980928 into shape (3648,2736,3)
    __cause__ = None
    __class__ = <class 'ValueError'>
    __context__ = ValueError('cannot reshape array of size 9980928 into shape (3648,2736,4)')
    __delattr__ = <method-wrapper '__delattr__' of ValueError object>
    __dict__ = {}
    __dir__ = <built-in method __dir__ of ValueError object>
    __doc__ = 'Inappropriate argument value (of correct type).'
    __eq__ = <method-wrapper '__eq__' of ValueError object>
    __format__ = <built-in method __format__ of ValueError object>
    __ge__ = <method-wrapper '__ge__' of ValueError object>
    __getattribute__ = <method-wrapper '__getattribute__' of ValueError object>
    __gt__ = <method-wrapper '__gt__' of ValueError object>
    __hash__ = <method-wrapper '__hash__' of ValueError object>
    __init__ = <method-wrapper '__init__' of ValueError object>
    __init_subclass__ = <built-in method __init_subclass__ of type object>
    __le__ = <method-wrapper '__le__' of ValueError object>
    __lt__ = <method-wrapper '__lt__' of ValueError object>
    __ne__ = <method-wrapper '__ne__' of ValueError object>
    __new__ = <built-in method __new__ of type object>
    __reduce__ = <built-in method __reduce__ of ValueError object>
    __reduce_ex__ = <built-in method __reduce_ex__ of ValueError object>
    __repr__ = <method-wrapper '__repr__' of ValueError object>
    __setattr__ = <method-wrapper '__setattr__' of ValueError object>
    __setstate__ = <built-in method __setstate__ of ValueError object>
    __sizeof__ = <built-in method __sizeof__ of ValueError object>
    __str__ = <method-wrapper '__str__' of ValueError object>
    __subclasshook__ = <built-in method __subclasshook__ of type object>
    __suppress_context__ = False
    __traceback__ = <traceback object>
    args = ('cannot reshape array of size 9980928 into shape (3648,2736,3)',)
    with_traceback = <built-in method with_traceback of ValueError object>

The above is a description of an error in a Python program.  Here is
the original traceback:

Traceback (most recent call last):
  File "E:\BaiduNetdiskWorkspace\Cloud_PythonProgramming\img-proc-app\plugins\ipc.py", line 103, in Q2CVimg
    CVimg = array(ptr, dtype=uint8).reshape(temp_shape)
ValueError: cannot reshape array of size 9980928 into shape (3648,2736,4)

During handling of the above exception, another exception occurred:

Traceback (most recent call last):
  File "E:\BaiduNetdiskWorkspace\Cloud_PythonProgramming\img-proc-app\widgets\ImgFrame.py", line 130, in dropEvent
    self.CV.Q2CVimg(self.imQT)
  File "E:\BaiduNetdiskWorkspace\Cloud_PythonProgramming\img-proc-app\plugins\ipc.py", line 110, in Q2CVimg
    CVimg = array(ptr, dtype=uint8).reshape(temp_shape)
ValueError: cannot reshape array of size 9980928 into shape (3648,2736,3)

