ValueError
Python 3.9.7: E:\Anaconda3\envs\imgproapp\python.exe
Fri Dec 10 15:26:02 2021

A problem occurred in a Python script.  Here is the sequence of
function calls leading up to the error, in the order they occurred.

 E:\BaiduNetdiskWorkspace\Cloud_PythonProgramming\img-proc-app\gui\subgui_edit.py in apply(self=<gui.subgui_edit.Ui_SubWindow object>)
 1425             else:
 1426                 self.graphicsView.coverPixmap()
 1427                 self.graphicsView.CVdst.Q2CVimg(self.graphicsView.imQT)
 1428 
 1429         if self.graphicsView.CVdst.img is not None:
self = <gui.subgui_edit.Ui_SubWindow object>
self.graphicsView = <widgets.ImgView.ImgView object>
self.graphicsView.CVdst = <plugins.ipc.AppImg object>
self.graphicsView.CVdst.Q2CVimg = <bound method AppImg.Q2CVimg of <plugins.ipc.AppImg object>>
self.graphicsView.imQT = <PyQt5.QtGui.QImage object>

 E:\BaiduNetdiskWorkspace\Cloud_PythonProgramming\img-proc-app\plugins\ipc.py in Q2CVimg(self=<plugins.ipc.AppImg object>, Qimg=<PyQt5.QtGui.QImage object>)
  108                 ptr = Qimg.bits()
  109                 ptr.setsize(Qimg.byteCount())
  110                 CVimg = np.array(ptr, dtype=np.uint8).reshape(temp_shape)
  111                 CVimg = CVimg[..., ::-1]
  112 
CVimg undefined
global np = <module 'numpy' from 'E:\\Anaconda3\\envs\\imgproapp\\lib\\site-packages\\numpy\\__init__.py'>
np.array = <built-in function array>
ptr = <sip.voidptr object>
dtype undefined
np.uint8 = <class 'numpy.uint8'>
).reshape = <method 'reshape' of 'numpy.generic' objects>
temp_shape = (2384, 1573, 3)
ValueError: cannot reshape array of size 11252480 into shape (2384,1573,3)
    __cause__ = None
    __class__ = <class 'ValueError'>
    __context__ = ValueError('cannot reshape array of size 11252480 into shape (2384,1573,4)')
    __delattr__ = <method-wrapper '__delattr__' of ValueError object>
    __dict__ = {}
    __dir__ = <built-in method __dir__ of ValueError object>
    __doc__ = 'Inappropriate argument value (of correct type).'
    __eq__ = <method-wrapper '__eq__' of ValueError object>
    __format__ = <built-in method __format__ of ValueError object>
    __ge__ = <method-wrapper '__ge__' of ValueError object>
    __getattribute__ = <method-wrapper '__getattribute__' of ValueError object>
    __gt__ = <method-wrapper '__gt__' of ValueError object>
    __hash__ = <method-wrapper '__hash__' of ValueError object>
    __init__ = <method-wrapper '__init__' of ValueError object>
    __init_subclass__ = <built-in method __init_subclass__ of type object>
    __le__ = <method-wrapper '__le__' of ValueError object>
    __lt__ = <method-wrapper '__lt__' of ValueError object>
    __ne__ = <method-wrapper '__ne__' of ValueError object>
    __new__ = <built-in method __new__ of type object>
    __reduce__ = <built-in method __reduce__ of ValueError object>
    __reduce_ex__ = <built-in method __reduce_ex__ of ValueError object>
    __repr__ = <method-wrapper '__repr__' of ValueError object>
    __setattr__ = <method-wrapper '__setattr__' of ValueError object>
    __setstate__ = <built-in method __setstate__ of ValueError object>
    __sizeof__ = <built-in method __sizeof__ of ValueError object>
    __str__ = <method-wrapper '__str__' of ValueError object>
    __subclasshook__ = <built-in method __subclasshook__ of type object>
    __suppress_context__ = False
    __traceback__ = <traceback object>
    args = ('cannot reshape array of size 11252480 into shape (2384,1573,3)',)
    with_traceback = <built-in method with_traceback of ValueError object>

The above is a description of an error in a Python program.  Here is
the original traceback:

Traceback (most recent call last):
  File "E:\BaiduNetdiskWorkspace\Cloud_PythonProgramming\img-proc-app\plugins\ipc.py", line 103, in Q2CVimg
    CVimg = np.array(ptr, dtype=np.uint8).reshape(temp_shape)
ValueError: cannot reshape array of size 11252480 into shape (2384,1573,4)

During handling of the above exception, another exception occurred:

Traceback (most recent call last):
  File "E:\BaiduNetdiskWorkspace\Cloud_PythonProgramming\img-proc-app\gui\subgui_edit.py", line 1427, in apply
    self.graphicsView.CVdst.Q2CVimg(self.graphicsView.imQT)
  File "E:\BaiduNetdiskWorkspace\Cloud_PythonProgramming\img-proc-app\plugins\ipc.py", line 110, in Q2CVimg
    CVimg = np.array(ptr, dtype=np.uint8).reshape(temp_shape)
ValueError: cannot reshape array of size 11252480 into shape (2384,1573,3)

